[2024-05-09T02:34:41.183+0000] {local_task_job_runner.py:120} INFO - ::group::Pre task execution logs
[2024-05-09T02:34:41.309+0000] {taskinstance.py:2073} INFO - Dependencies all met for dep_context=non-requeueable deps ti=<TaskInstance: my_dag_trigger.task_id_A scheduled__2024-05-08T00:00:00+00:00 [queued]>
[2024-05-09T02:34:41.348+0000] {taskinstance.py:2073} INFO - Dependencies all met for dep_context=requeueable deps ti=<TaskInstance: my_dag_trigger.task_id_A scheduled__2024-05-08T00:00:00+00:00 [queued]>
[2024-05-09T02:34:41.350+0000] {taskinstance.py:2303} INFO - Starting attempt 1 of 3
[2024-05-09T02:34:41.415+0000] {taskinstance.py:2327} INFO - Executing <Task(PythonOperator): task_id_A> on 2024-05-08 00:00:00+00:00
[2024-05-09T02:34:41.443+0000] {warnings.py:110} WARNING - /home/***/.local/lib/python3.12/site-packages/***/task/task_runner/standard_task_runner.py:61: DeprecationWarning: This process (pid=3741) is multi-threaded, use of fork() may lead to deadlocks in the child.
  pid = os.fork()

[2024-05-09T02:34:41.459+0000] {standard_task_runner.py:63} INFO - Started process 3745 to run task
[2024-05-09T02:34:41.448+0000] {standard_task_runner.py:90} INFO - Running: ['***', 'tasks', 'run', 'my_dag_trigger', 'task_id_A', 'scheduled__2024-05-08T00:00:00+00:00', '--job-id', '48', '--raw', '--subdir', 'DAGS_FOLDER/my_dag_trigger.py', '--cfg-path', '/tmp/tmpz1rmvh09']
[2024-05-09T02:34:41.481+0000] {standard_task_runner.py:91} INFO - Job 48: Subtask task_id_A
[2024-05-09T02:34:41.683+0000] {task_command.py:426} INFO - Running <TaskInstance: my_dag_trigger.task_id_A scheduled__2024-05-08T00:00:00+00:00 [running]> on host 2b3626ba2b72
[2024-05-09T02:34:42.083+0000] {taskinstance.py:2644} INFO - Exporting env vars: AIRFLOW_CTX_DAG_OWNER='satyendra' AIRFLOW_CTX_DAG_ID='my_dag_trigger' AIRFLOW_CTX_TASK_ID='task_id_A' AIRFLOW_CTX_EXECUTION_DATE='2024-05-08T00:00:00+00:00' AIRFLOW_CTX_TRY_NUMBER='1' AIRFLOW_CTX_DAG_RUN_ID='scheduled__2024-05-08T00:00:00+00:00'
[2024-05-09T02:34:42.094+0000] {taskinstance.py:430} INFO - ::endgroup::
[2024-05-09T02:34:42.097+0000] {taskinstance.py:441} INFO - ::group::Post task execution logs
[2024-05-09T02:34:42.098+0000] {taskinstance.py:2890} ERROR - Task failed with exception
Traceback (most recent call last):
  File "/home/airflow/.local/lib/python3.12/site-packages/airflow/models/taskinstance.py", line 465, in _execute_task
    result = _execute_callable(context=context, **execute_callable_kwargs)
             ^^^^^^^^^^^^^^^^^^^^^^^^^^^^^^^^^^^^^^^^^^^^^^^^^^^^^^^^^^^^^
  File "/home/airflow/.local/lib/python3.12/site-packages/airflow/models/taskinstance.py", line 432, in _execute_callable
    return execute_callable(context=context, **execute_callable_kwargs)
           ^^^^^^^^^^^^^^^^^^^^^^^^^^^^^^^^^^^^^^^^^^^^^^^^^^^^^^^^^^^^
  File "/home/airflow/.local/lib/python3.12/site-packages/airflow/models/baseoperator.py", line 400, in wrapper
    return func(self, *args, **kwargs)
           ^^^^^^^^^^^^^^^^^^^^^^^^^^^
  File "/home/airflow/.local/lib/python3.12/site-packages/airflow/operators/python.py", line 235, in execute
    return_value = self.execute_callable()
                   ^^^^^^^^^^^^^^^^^^^^^^^
  File "/home/airflow/.local/lib/python3.12/site-packages/airflow/operators/python.py", line 252, in execute_callable
    return self.python_callable(*self.op_args, **self.op_kwargs)
           ^^^^^^^^^^^^^^^^^^^^^^^^^^^^^^^^^^^^^^^^^^^^^^^^^^^^^
  File "/opt/airflow/dags/my_dag_trigger.py", line 27, in <lambda>
    python_callable=lambda: raise_exception("Failure of task")
                            ^^^^^^^^^^^^^^^
NameError: name 'raise_exception' is not defined. Did you mean: 'BaseException'?
[2024-05-09T02:34:42.242+0000] {taskinstance.py:1205} INFO - Marking task as UP_FOR_RETRY. dag_id=my_dag_trigger, task_id=task_id_A, execution_date=20240508T000000, start_date=20240509T023441, end_date=20240509T023442
[2024-05-09T02:34:42.374+0000] {standard_task_runner.py:110} ERROR - Failed to execute job 48 for task task_id_A (name 'raise_exception' is not defined; 3745)
[2024-05-09T02:34:42.452+0000] {local_task_job_runner.py:240} INFO - Task exited with return code 1
[2024-05-09T02:34:42.529+0000] {taskinstance.py:3482} INFO - 0 downstream tasks scheduled from follow-on schedule check
[2024-05-09T02:34:42.536+0000] {local_task_job_runner.py:222} INFO - ::endgroup::
