[2024-05-09T02:37:56.299+0000] {task_context_logger.py:104} ERROR - Executor reports task instance <TaskInstance: my_dag_trigger.task_id_A scheduled__2024-05-08T00:00:00+00:00 [queued]> finished (failed) although the task says it's queued. (Info: None) Was the task killed externally?
