[2024-05-09T02:40:01.822+0000] {local_task_job_runner.py:120} INFO - ::group::Pre task execution logs
[2024-05-09T02:40:01.891+0000] {taskinstance.py:2073} INFO - Dependencies all met for dep_context=non-requeueable deps ti=<TaskInstance: my_dag_trigger.task_id_B scheduled__2024-05-08T00:00:00+00:00 [queued]>
[2024-05-09T02:40:01.923+0000] {taskinstance.py:2073} INFO - Dependencies all met for dep_context=requeueable deps ti=<TaskInstance: my_dag_trigger.task_id_B scheduled__2024-05-08T00:00:00+00:00 [queued]>
[2024-05-09T02:40:01.924+0000] {taskinstance.py:2303} INFO - Starting attempt 3 of 3
[2024-05-09T02:40:01.960+0000] {taskinstance.py:2327} INFO - Executing <Task(PythonOperator): task_id_B> on 2024-05-08 00:00:00+00:00
[2024-05-09T02:40:01.979+0000] {standard_task_runner.py:90} INFO - Running: ['***', 'tasks', 'run', 'my_dag_trigger', 'task_id_B', 'scheduled__2024-05-08T00:00:00+00:00', '--job-id', '49', '--raw', '--subdir', 'DAGS_FOLDER/my_dag_trigger.py', '--cfg-path', '/tmp/tmpfdh23zf2']
[2024-05-09T02:40:01.985+0000] {warnings.py:110} WARNING - /home/***/.local/lib/python3.12/site-packages/***/task/task_runner/standard_task_runner.py:61: DeprecationWarning: This process (pid=3800) is multi-threaded, use of fork() may lead to deadlocks in the child.
  pid = os.fork()

[2024-05-09T02:40:01.989+0000] {standard_task_runner.py:63} INFO - Started process 3804 to run task
[2024-05-09T02:40:01.987+0000] {standard_task_runner.py:91} INFO - Job 49: Subtask task_id_B
[2024-05-09T02:40:02.152+0000] {task_command.py:426} INFO - Running <TaskInstance: my_dag_trigger.task_id_B scheduled__2024-05-08T00:00:00+00:00 [running]> on host 2b3626ba2b72
[2024-05-09T02:40:02.380+0000] {taskinstance.py:2644} INFO - Exporting env vars: AIRFLOW_CTX_DAG_OWNER='satyendra' AIRFLOW_CTX_DAG_ID='my_dag_trigger' AIRFLOW_CTX_TASK_ID='task_id_B' AIRFLOW_CTX_EXECUTION_DATE='2024-05-08T00:00:00+00:00' AIRFLOW_CTX_TRY_NUMBER='3' AIRFLOW_CTX_DAG_RUN_ID='scheduled__2024-05-08T00:00:00+00:00'
[2024-05-09T02:40:02.384+0000] {taskinstance.py:430} INFO - ::endgroup::
[2024-05-09T02:40:02.385+0000] {taskinstance.py:441} INFO - ::group::Post task execution logs
[2024-05-09T02:40:02.386+0000] {taskinstance.py:2890} ERROR - Task failed with exception
Traceback (most recent call last):
  File "/home/airflow/.local/lib/python3.12/site-packages/airflow/models/taskinstance.py", line 465, in _execute_task
    result = _execute_callable(context=context, **execute_callable_kwargs)
             ^^^^^^^^^^^^^^^^^^^^^^^^^^^^^^^^^^^^^^^^^^^^^^^^^^^^^^^^^^^^^
  File "/home/airflow/.local/lib/python3.12/site-packages/airflow/models/taskinstance.py", line 432, in _execute_callable
    return execute_callable(context=context, **execute_callable_kwargs)
           ^^^^^^^^^^^^^^^^^^^^^^^^^^^^^^^^^^^^^^^^^^^^^^^^^^^^^^^^^^^^
  File "/home/airflow/.local/lib/python3.12/site-packages/airflow/models/baseoperator.py", line 400, in wrapper
    return func(self, *args, **kwargs)
           ^^^^^^^^^^^^^^^^^^^^^^^^^^^
  File "/home/airflow/.local/lib/python3.12/site-packages/airflow/operators/python.py", line 235, in execute
    return_value = self.execute_callable()
                   ^^^^^^^^^^^^^^^^^^^^^^^
  File "/home/airflow/.local/lib/python3.12/site-packages/airflow/operators/python.py", line 252, in execute_callable
    return self.python_callable(*self.op_args, **self.op_kwargs)
           ^^^^^^^^^^^^^^^^^^^^^^^^^^^^^^^^^^^^^^^^^^^^^^^^^^^^^
  File "/opt/airflow/dags/my_dag_trigger.py", line 32, in <lambda>
    python_callable=lambda: raise_exception("Failure of task")
                            ^^^^^^^^^^^^^^^
NameError: name 'raise_exception' is not defined. Did you mean: 'BaseException'?
[2024-05-09T02:40:02.424+0000] {taskinstance.py:1205} INFO - Marking task as FAILED. dag_id=my_dag_trigger, task_id=task_id_B, execution_date=20240508T000000, start_date=20240509T024001, end_date=20240509T024002
[2024-05-09T02:40:02.451+0000] {standard_task_runner.py:110} ERROR - Failed to execute job 49 for task task_id_B (name 'raise_exception' is not defined; 3804)
[2024-05-09T02:40:02.495+0000] {local_task_job_runner.py:240} INFO - Task exited with return code 1
[2024-05-09T02:40:02.549+0000] {taskinstance.py:3482} INFO - 0 downstream tasks scheduled from follow-on schedule check
[2024-05-09T02:40:02.555+0000] {local_task_job_runner.py:222} INFO - ::endgroup::
