[2024-05-09T01:53:39.058+0000] {local_task_job_runner.py:120} INFO - ::group::Pre task execution logs
[2024-05-09T01:53:39.280+0000] {taskinstance.py:2073} INFO - Dependencies all met for dep_context=non-requeueable deps ti=<TaskInstance: my_dag_v1.choose_best_model manual__2024-05-09T01:28:05.298020+00:00 [queued]>
[2024-05-09T01:53:39.327+0000] {taskinstance.py:2073} INFO - Dependencies all met for dep_context=requeueable deps ti=<TaskInstance: my_dag_v1.choose_best_model manual__2024-05-09T01:28:05.298020+00:00 [queued]>
[2024-05-09T01:53:39.330+0000] {taskinstance.py:2303} INFO - Starting attempt 6 of 6
[2024-05-09T01:53:39.419+0000] {taskinstance.py:2327} INFO - Executing <Task(BranchPythonOperator): choose_best_model> on 2024-05-09 01:28:05.298020+00:00
[2024-05-09T01:53:39.451+0000] {standard_task_runner.py:90} INFO - Running: ['***', 'tasks', 'run', 'my_dag_v1', 'choose_best_model', 'manual__2024-05-09T01:28:05.298020+00:00', '--job-id', '27', '--raw', '--subdir', 'DAGS_FOLDER/my_dag.py', '--cfg-path', '/tmp/tmp9e0b7vgt']
[2024-05-09T01:53:39.445+0000] {warnings.py:110} WARNING - /home/***/.local/lib/python3.12/site-packages/***/task/task_runner/standard_task_runner.py:61: DeprecationWarning: This process (pid=3202) is multi-threaded, use of fork() may lead to deadlocks in the child.
  pid = os.fork()

[2024-05-09T01:53:39.470+0000] {standard_task_runner.py:91} INFO - Job 27: Subtask choose_best_model
[2024-05-09T01:53:39.470+0000] {standard_task_runner.py:63} INFO - Started process 3207 to run task
[2024-05-09T01:53:39.648+0000] {task_command.py:426} INFO - Running <TaskInstance: my_dag_v1.choose_best_model manual__2024-05-09T01:28:05.298020+00:00 [running]> on host 2b3626ba2b72
[2024-05-09T01:53:39.944+0000] {taskinstance.py:2644} INFO - Exporting env vars: AIRFLOW_CTX_DAG_OWNER='satyendra' AIRFLOW_CTX_DAG_ID='my_dag_v1' AIRFLOW_CTX_TASK_ID='choose_best_model' AIRFLOW_CTX_EXECUTION_DATE='2024-05-09T01:28:05.298020+00:00' AIRFLOW_CTX_TRY_NUMBER='6' AIRFLOW_CTX_DAG_RUN_ID='manual__2024-05-09T01:28:05.298020+00:00'
[2024-05-09T01:53:39.947+0000] {taskinstance.py:430} INFO - ::endgroup::
[2024-05-09T01:53:39.951+0000] {baseoperator.py:399} WARNING - BranchPythonOperator.execute cannot be called outside TaskInstance!
[2024-05-09T01:53:39.952+0000] {taskinstance.py:441} INFO - ::group::Post task execution logs
[2024-05-09T01:53:39.953+0000] {taskinstance.py:2890} ERROR - Task failed with exception
Traceback (most recent call last):
  File "/home/airflow/.local/lib/python3.12/site-packages/airflow/models/taskinstance.py", line 465, in _execute_task
    result = _execute_callable(context=context, **execute_callable_kwargs)
             ^^^^^^^^^^^^^^^^^^^^^^^^^^^^^^^^^^^^^^^^^^^^^^^^^^^^^^^^^^^^^
  File "/home/airflow/.local/lib/python3.12/site-packages/airflow/models/taskinstance.py", line 432, in _execute_callable
    return execute_callable(context=context, **execute_callable_kwargs)
           ^^^^^^^^^^^^^^^^^^^^^^^^^^^^^^^^^^^^^^^^^^^^^^^^^^^^^^^^^^^^
  File "/home/airflow/.local/lib/python3.12/site-packages/airflow/models/baseoperator.py", line 400, in wrapper
    return func(self, *args, **kwargs)
           ^^^^^^^^^^^^^^^^^^^^^^^^^^^
  File "/home/airflow/.local/lib/python3.12/site-packages/airflow/operators/python.py", line 269, in execute
    return self.do_branch(context, super().execute(context))
                                   ^^^^^^^^^^^^^^^^^^^^^^^^
  File "/home/airflow/.local/lib/python3.12/site-packages/airflow/models/baseoperator.py", line 400, in wrapper
    return func(self, *args, **kwargs)
           ^^^^^^^^^^^^^^^^^^^^^^^^^^^
  File "/home/airflow/.local/lib/python3.12/site-packages/airflow/operators/python.py", line 235, in execute
    return_value = self.execute_callable()
                   ^^^^^^^^^^^^^^^^^^^^^^^
  File "/home/airflow/.local/lib/python3.12/site-packages/airflow/operators/python.py", line 252, in execute_callable
    return self.python_callable(*self.op_args, **self.op_kwargs)
           ^^^^^^^^^^^^^^^^^^^^^^^^^^^^^^^^^^^^^^^^^^^^^^^^^^^^^
  File "/opt/airflow/dags/my_dag.py", line 17, in choose_best_model
    accuracies=ti.xcom_pull(taskids=[
               ^^^^^^^^^^^^^^^^^^^^^^
  File "/home/airflow/.local/lib/python3.12/site-packages/airflow/utils/session.py", line 79, in wrapper
    return func(*args, session=session, **kwargs)
           ^^^^^^^^^^^^^^^^^^^^^^^^^^^^^^^^^^^^^^
TypeError: TaskInstance.xcom_pull() got an unexpected keyword argument 'taskids'
[2024-05-09T01:53:39.980+0000] {taskinstance.py:1205} INFO - Marking task as FAILED. dag_id=my_dag_v1, task_id=choose_best_model, execution_date=20240509T012805, start_date=20240509T015339, end_date=20240509T015339
[2024-05-09T01:53:40.013+0000] {standard_task_runner.py:110} ERROR - Failed to execute job 27 for task choose_best_model (TaskInstance.xcom_pull() got an unexpected keyword argument 'taskids'; 3207)
[2024-05-09T01:53:40.073+0000] {local_task_job_runner.py:240} INFO - Task exited with return code 1
[2024-05-09T01:53:40.145+0000] {taskinstance.py:3482} INFO - 0 downstream tasks scheduled from follow-on schedule check
[2024-05-09T01:53:40.151+0000] {local_task_job_runner.py:222} INFO - ::endgroup::
