[2024-05-09T02:08:01.131+0000] {task_context_logger.py:104} ERROR - Executor reports task instance <TaskInstance: my_dag_v1.training_model_A manual__2024-05-09T02:07:43.320809+00:00 [queued]> finished (failed) although the task says it's queued. (Info: None) Was the task killed externally?
